<?xml version="1.0" encoding="utf-8"?>
<!-- This URDF was automatically created by SolidWorks to URDF Exporter! Originally created by Stephen Brawner (brawner@gmail.com) 
     Commit Version: 1.6.0-4-g7f85cfe  Build Version: 1.6.7995.38578
     For more information, please see http://wiki.ros.org/sw_urdf_exporter -->
<robot
  name="TSD2">
  <link
    name="base_link">
    <inertial>
      <origin
        xyz="-0.0086842 -0.001824 0.0066951"
        rpy="0 0 0" />
      <mass
        value="19" />
      <inertia
        ixx="0.11844"
        ixy="-3.6398E-05"
        ixz="-8.0593E-05"
        iyy="0.21487"
        iyz="0.00086584"
        izz="0.28797" />
    </inertial>
    <visual>
      <origin
        xyz="0 0 0"
        rpy="0 0 0" />
      <geometry>
        <mesh
          filename="package://TSD2/meshes/base_link.STL" />
      </geometry>
      <material
        name="">
        <color
          rgba="0.89804 0.91765 0.92941 1" />
      </material>
    </visual>
    <collision>
      <origin
        xyz="0 0 0"
        rpy="0 0 0" />
      <geometry>
        <mesh
          filename="package://TSD2/meshes/base_link.STL" />
      </geometry>
    </collision>
  </link>
  <link
    name="FR_hip">
    <inertial>
      <origin
        xyz="0.022631 -0.080831 -2.7672E-05"
        rpy="0 0 0" />
      <mass
        value="0.89491" />
      <inertia
        ixx="0.0010335"
        ixy="3.2218E-05"
        ixz="-7.4568E-06"
        iyy="0.0010798"
        iyz="-5.3424E-08"
        izz="0.0011441" />
    </inertial>
    <visual>
      <origin
        xyz="0 0 0"
        rpy="0 0 0" />
      <geometry>
        <mesh
          filename="package://TSD2/meshes/FR_hip.STL" />
      </geometry>
      <material
        name="">
        <color
          rgba="0.89804 0.91765 0.92941 1" />
      </material>
    </visual>
    <collision>
      <origin
        xyz="0 0 0"
        rpy="0 0 0" />
      <geometry>
        <mesh
          filename="package://TSD2/meshes/FR_hip.STL" />
      </geometry>
    </collision>
  </link>
  <joint
    name="FR_hip_joint"
    type="revolute">
    <origin
      xyz="0.2645 -0.08 0"
      rpy="0 0 0" />
    <parent
      link="base_link" />
    <child
      link="FR_hip" />
    <axis
      xyz="1 0 0" />
    <limit
      lower="-0.61087"
      upper="0.43633"
      effort="170"
      velocity="18.85" />
  </joint>
  <link
    name="FR_thigh">
    <inertial>
      <origin
        xyz="5.4425E-05 0.018201 -0.15086"
        rpy="0 0 0" />
      <mass
        value="1.0663" />
      <inertia
        ixx="0.0030889"
        ixy="2.1539E-06"
        ixz="3.3557E-08"
        iyy="0.0034689"
        iyz="0.00010095"
        izz="0.00094634" />
    </inertial>
    <visual>
      <origin
        xyz="0 0 0"
        rpy="0 0 0" />
      <geometry>
        <mesh
          filename="package://TSD2/meshes/FR_thigh.STL" />
      </geometry>
      <material
        name="">
        <color
          rgba="1 0.54902 0 1" />
      </material>
    </visual>
    <collision>
      <origin
        xyz="0 0 0"
        rpy="0 0 0" />
      <geometry>
        <mesh
          filename="package://TSD2/meshes/FR_thigh.STL" />
      </geometry>
    </collision>
  </link>
  <joint
    name="FR_thigh_joint"
    type="revolute">
    <origin
      xyz="0.024 -0.1595 0"
      rpy="0 0 0" />
    <parent
      link="FR_hip" />
    <child
      link="FR_thigh" />
    <axis
      xyz="0 1 0" />
    <limit
      lower="-2.4435"
      upper="2.4435"
      effort="170"
      velocity="18.85" />
  </joint>
  <link
    name="FR_calf">
    <inertial>
      <origin
        xyz="-0.000129129815911011 -0.0292018673004593 -0.162928540961205"
        rpy="0 0 0" />
      <mass
        value="1.0911925295716" />
      <inertia
        ixx="0.00471928904754399"
        ixy="5.12461716108306E-06"
        ixz="-4.47843204170971E-07"
        iyy="0.00505716636135159"
        iyz="-0.000234413711936698"
        izz="0.000982245502544423" />
    </inertial>
    <visual>
      <origin
        xyz="0 0 0"
        rpy="0 0 0" />
      <geometry>
        <mesh
          filename="package://TSD2/meshes/FR_calf.STL" />
      </geometry>
      <material
        name="">
        <color
          rgba="0.0392156862745098 0.490196078431373 0.709803921568627 1" />
      </material>
    </visual>
    <collision>
      <origin
        xyz="0 0 0"
        rpy="0 0 0" />
      <geometry>
        <mesh
          filename="package://TSD2/meshes/FR_calf.STL" />
      </geometry>
    </collision>
  </link>
  <joint
    name="FR_calf_joint"
    type="revolute">
    <origin
      xyz="0 0.0714 -0.225"
      rpy="0 0 0" />
    <parent
      link="FR_thigh" />
    <child
      link="FR_calf" />
    <axis
      xyz="0 -1 0" />
    <limit
      lower="-2.7576"
      upper="2.5831"
      effort="170"
      velocity="18.85" />
  </joint>
  <link
    name="FR_wheel">
    <inertial>
      <origin
        xyz="-2.85E-05 0.0019198 4.9367E-05"
        rpy="0 0 0" />
      <mass
        value="0.80976" />
      <inertia
        ixx="0.0024884"
        ixy="-2.3439E-07"
        ixz="-1.2186E-06"
        iyy="0.0046193"
        iyz="4.0597E-07"
        izz="0.0024898" />
    </inertial>
    <visual>
      <origin
        xyz="0 0 0"
        rpy="0 0 0" />
      <geometry>
        <mesh
          filename="package://TSD2/meshes/FR_wheel.STL" />
      </geometry>
      <material
        name="">
        <color
          rgba="0.34118 0.83922 0.41176 1" />
      </material>
    </visual>
    <collision>
      <origin
        xyz="0 0 0"
        rpy="0 0 0" />
      <geometry>
        <mesh
          filename="package://TSD2/meshes/FR_wheel.STL" />
      </geometry>
    </collision>
  </link>
  <joint
    name="FR_wheel_joint"
    type="revolute">
    <origin
      xyz="0 -0.0954 -0.272"
      rpy="0 0 0" />
    <parent
      link="FR_calf" />
    <child
      link="FR_wheel" />
    <axis
      xyz="0 -1 0" />
    <limit
      effort="38"
      velocity="61.7846555205993" />
  </joint>
  <link
    name="FL_hip">
    <inertial>
      <origin
        xyz="0.0226310221775106 0.0808307943976452 2.76727872396542E-05"
        rpy="0 0 0" />
      <mass
        value="0.894912703451862" />
      <inertia
        ixx="0.0010334771676679"
        ixy="-3.22181651406533E-05"
        ixz="7.45681442154323E-06"
        iyy="0.00107984361506111"
        iyz="-5.34371482645339E-08"
        izz="0.00114407402550678" />
    </inertial>
    <visual>
      <origin
        xyz="0 0 0"
        rpy="0 0 0" />
      <geometry>
        <mesh
          filename="package://TSD2/meshes/FL_hip.STL" />
      </geometry>
      <material
        name="">
        <color
          rgba="0.898039215686275 0.917647058823529 0.929411764705882 1" />
      </material>
    </visual>
    <collision>
      <origin
        xyz="0 0 0"
        rpy="0 0 0" />
      <geometry>
        <mesh
          filename="package://TSD2/meshes/FL_hip.STL" />
      </geometry>
    </collision>
  </link>
  <joint
    name="FL_hip_joint"
    type="revolute">
    <origin
      xyz="0.2645 0.08 0"
      rpy="0 0 0" />
    <parent
      link="base_link" />
    <child
      link="FL_hip" />
    <axis
      xyz="1 0 0" />
    <limit
      lower="-0.61087"
      upper="0.43633"
      effort="170"
      velocity="18.8495559215388" />
  </joint>
  <link
    name="FL_thigh">
    <inertial>
      <origin
        xyz="-5.44237498041888E-05 -0.0182014688357576 -0.150861409441496"
        rpy="0 0 0" />
      <mass
        value="1.06633586725301" />
      <inertia
        ixx="0.00308887299016947"
        ixy="2.15392224301937E-06"
        ixz="-3.3555137962054E-08"
        iyy="0.00346888029307935"
        iyz="-0.000100954236287448"
        izz="0.00094634359854833" />
    </inertial>
    <visual>
      <origin
        xyz="0 0 0"
        rpy="0 0 0" />
      <geometry>
        <mesh
          filename="package://TSD2/meshes/FL_thigh.STL" />
      </geometry>
      <material
        name="">
        <color
          rgba="1 0.549019607843137 0 1" />
      </material>
    </visual>
    <collision>
      <origin
        xyz="0 0 0"
        rpy="0 0 0" />
      <geometry>
        <mesh
          filename="package://TSD2/meshes/FL_thigh.STL" />
      </geometry>
    </collision>
  </link>
  <joint
    name="FL_thigh_joint"
    type="revolute">
    <origin
      xyz="0.024 0.1595 0"
      rpy="0 0 0" />
    <parent
      link="FL_hip" />
    <child
      link="FL_thigh" />
    <axis
      xyz="0 -1 0" />
    <limit
      lower="-2.4435"
      upper="2.4435"
      effort="170"
      velocity="18.8495559215388" />
  </joint>
  <link
    name="FL_calf">
    <inertial>
      <origin
        xyz="0.000129129816000551 0.0292018673000794 -0.162928540959482"
        rpy="0 0 0" />
      <mass
        value="1.09119252955386" />
      <inertia
        ixx="0.00471928904754912"
        ixy="5.12461716084131E-06"
        ixz="4.47843224770219E-07"
        iyy="0.00505716636132713"
        iyz="0.000234413711936672"
        izz="0.000982245502514568" />
    </inertial>
    <visual>
      <origin
        xyz="0 0 0"
        rpy="0 0 0" />
      <geometry>
        <mesh
          filename="package://TSD2/meshes/FL_calf.STL" />
      </geometry>
      <material
        name="">
        <color
          rgba="1 0.168627450980392 0.168627450980392 1" />
      </material>
    </visual>
    <collision>
      <origin
        xyz="0 0 0"
        rpy="0 0 0" />
      <geometry>
        <mesh
          filename="package://TSD2/meshes/FL_calf.STL" />
      </geometry>
    </collision>
  </link>
  <joint
    name="FL_calf_joint"
    type="revolute">
    <origin
      xyz="0 -0.0714 -0.225"
      rpy="0 0 0" />
    <parent
      link="FL_thigh" />
    <child
      link="FL_calf" />
    <axis
      xyz="0 1 0" />
    <limit
      lower="-2.7576"
      upper="2.5831"
      effort="170"
      velocity="18.8495559215388" />
  </joint>
  <link
    name="FL_wheel">
    <inertial>
      <origin
        xyz="2.85004469314232E-05 -0.00191982582822392 4.93665264903465E-05"
        rpy="0 0 0" />
      <mass
        value="0.809759882175001" />
      <inertia
        ixx="0.00248836886460222"
        ixy="-2.34386082319347E-07"
        ixz="1.21855271308788E-06"
        iyy="0.00461927313692848"
        iyz="-4.05972264686035E-07"
        izz="0.00248977603008749" />
    </inertial>
    <visual>
      <origin
        xyz="0 0 0"
        rpy="0 0 0" />
      <geometry>
        <mesh
          filename="package://TSD2/meshes/FL_wheel.STL" />
      </geometry>
      <material
        name="">
        <color
          rgba="0.341176470588235 0.83921568627451 0.411764705882353 1" />
      </material>
    </visual>
    <collision>
      <origin
        xyz="0 0 0"
        rpy="0 0 0" />
      <geometry>
        <mesh
          filename="package://TSD2/meshes/FL_wheel.STL" />
      </geometry>
    </collision>
  </link>
  <joint
    name="FL_wheel_joint"
    type="revolute">
    <origin
      xyz="0 0.0954 -0.272"
      rpy="0 0 0" />
    <parent
      link="FL_calf" />
    <child
      link="FL_wheel" />
    <axis
      xyz="0 1 0" />
    <limit
      effort="38"
      velocity="61.7846555205993" />
  </joint>
  <link
    name="RR_hip">
    <inertial>
      <origin
        xyz="-0.0226310218502942 -0.0808307931480784 2.76715585654124E-05"
        rpy="0 0 0" />
      <mass
        value="0.894912736354396" />
      <inertia
        ixx="0.00103347721312902"
        ixy="-3.22181627957963E-05"
        ixz="-7.45680643434527E-06"
        iyy="0.00107984365619954"
        iyz="5.34239111815802E-08"
        izz="0.00114407403320252" />
    </inertial>
    <visual>
      <origin
        xyz="0 0 0"
        rpy="0 0 0" />
      <geometry>
        <mesh
          filename="package://TSD2/meshes/RR_hip.STL" />
      </geometry>
      <material
        name="">
        <color
          rgba="0.898039215686275 0.917647058823529 0.929411764705882 1" />
      </material>
    </visual>
    <collision>
      <origin
        xyz="0 0 0"
        rpy="0 0 0" />
      <geometry>
        <mesh
          filename="package://TSD2/meshes/RR_hip.STL" />
      </geometry>
    </collision>
  </link>
  <joint
    name="RR_hip_joint"
    type="revolute">
    <origin
      xyz="-0.2645 -0.08 0"
      rpy="0 0 0" />
    <parent
      link="base_link" />
    <child
      link="RR_hip" />
    <axis
      xyz="-1 0 0" />
    <limit
      lower="-0.61087"
      upper="0.43633"
      effort="170"
      velocity="18.8495559215388" />
  </joint>
  <link
    name="RR_thigh">
    <inertial>
      <origin
        xyz="5.44247389386854E-05 0.0182014717306178 -0.150861416012514"
        rpy="0 0 0" />
      <mass
        value="1.06633596228652" />
      <inertia
        ixx="0.00308887307166983"
        ixy="2.15389365742748E-06"
        ixz="3.35571197322717E-08"
        iyy="0.00346888032405048"
        iyz="0.000100954241126325"
        izz="0.000946343679472054" />
    </inertial>
    <visual>
      <origin
        xyz="0 0 0"
        rpy="0 0 0" />
      <geometry>
        <mesh
          filename="package://TSD2/meshes/RR_thigh.STL" />
      </geometry>
      <material
        name="">
        <color
          rgba="1 0.549019607843137 0 1" />
      </material>
    </visual>
    <collision>
      <origin
        xyz="0 0 0"
        rpy="0 0 0" />
      <geometry>
        <mesh
          filename="package://TSD2/meshes/RR_thigh.STL" />
      </geometry>
    </collision>
  </link>
  <joint
    name="RR_thigh_joint"
    type="revolute">
    <origin
      xyz="-0.024 -0.1595 0"
      rpy="0 0 0" />
    <parent
      link="RR_hip" />
    <child
      link="RR_thigh" />
    <axis
      xyz="0 1 0" />
    <limit
      lower="-2.4435"
      upper="2.4435"
      effort="170"
      velocity="18.8495559215388" />
  </joint>
  <link
    name="RR_calf">
    <inertial>
      <origin
        xyz="-0.000129129816574314 -0.0292018673004579 -0.162928540961274"
        rpy="0 0 0" />
      <mass
        value="1.09119252957151" />
      <inertia
        ixx="0.00471928904754991"
        ixy="5.12461715924824E-06"
        ixz="-4.47843228632589E-07"
        iyy="0.0050571663613513"
        iyz="-0.000234413711936906"
        izz="0.000982245502538196" />
    </inertial>
    <visual>
      <origin
        xyz="0 0 0"
        rpy="0 0 0" />
      <geometry>
        <mesh
          filename="package://TSD2/meshes/RR_calf.STL" />
      </geometry>
      <material
        name="">
        <color
          rgba="0.0392156862745098 0.490196078431373 0.709803921568627 1" />
      </material>
    </visual>
    <collision>
      <origin
        xyz="0 0 0"
        rpy="0 0 0" />
      <geometry>
        <mesh
          filename="package://TSD2/meshes/RR_calf.STL" />
      </geometry>
    </collision>
  </link>
  <joint
    name="RR_calf_joint"
    type="revolute">
    <origin
      xyz="0 0.0714 -0.225"
      rpy="0 0 0" />
    <parent
      link="RR_thigh" />
    <child
      link="RR_calf" />
    <axis
      xyz="0 -1 0" />
    <limit
      lower="-2.7576"
      upper="2.5831"
      effort="170"
      velocity="18.8495559215388" />
  </joint>
  <link
    name="RR_wheel">
    <inertial>
      <origin
        xyz="-2.85004469314787E-05 0.00191982582822386 4.93665264902909E-05"
        rpy="0 0 0" />
      <mass
        value="0.809759882174997" />
      <inertia
        ixx="0.00248836886460221"
        ixy="-2.34386082319292E-07"
        ixz="-1.21855271308756E-06"
        iyy="0.00461927313692847"
        iyz="4.05972264685728E-07"
        izz="0.00248977603008748" />
    </inertial>
    <visual>
      <origin
        xyz="0 0 0"
        rpy="0 0 0" />
      <geometry>
        <mesh
          filename="package://TSD2/meshes/RR_wheel.STL" />
      </geometry>
      <material
        name="">
        <color
          rgba="1 1 0 1" />
      </material>
    </visual>
    <collision>
      <origin
        xyz="0 0 0"
        rpy="0 0 0" />
      <geometry>
        <mesh
          filename="package://TSD2/meshes/RR_wheel.STL" />
      </geometry>
    </collision>
  </link>
  <joint
    name="RR_wheel_joint"
    type="revolute">
    <origin
      xyz="0 -0.0954 -0.272"
      rpy="0 0 0" />
    <parent
      link="RR_calf" />
    <child
      link="RR_wheel" />
    <axis
      xyz="0 -1 0" />
    <limit
      effort="38"
      velocity="61.785" />
  </joint>
  <link
    name="RL_hip">
    <inertial>
      <origin
        xyz="0.018413 0.015515 -4.3808E-05"
        rpy="0 0 0" />
      <mass
        value="0.88356" />
      <inertia
        ixx="0.0011036"
        ixy="3.4473E-05"
        ixz="8.2027E-06"
        iyy="0.0009948"
        iyz="1.0567E-06"
        izz="0.0010646" />
    </inertial>
    <visual>
      <origin
        xyz="0 0 0"
        rpy="0 0 0" />
      <geometry>
        <mesh
          filename="package://TSD2/meshes/RL_hip.STL" />
      </geometry>
      <material
        name="">
        <color
          rgba="1 1 1 1" />
      </material>
    </visual>
    <collision>
      <origin
        xyz="0 0 0"
        rpy="0 0 0" />
      <geometry>
        <mesh
          filename="package://TSD2/meshes/RL_hip.STL" />
      </geometry>
    </collision>
  </link>
  <joint
    name="RL_hip_joint"
    type="revolute">
    <origin
      xyz="-0.2645 0.08 0"
      rpy="0 0 0" />
    <parent
      link="base_link" />
    <child
      link="RL_hip" />
    <axis
      xyz="-1 0 0" />
    <limit
      lower="-0.61087"
      upper="0.43633"
      effort="170"
      velocity="18.85" />
  </joint>
  <link
    name="RL_thigh">
    <inertial>
      <origin
        xyz="-5.44247170103374E-05 -0.0182014717412418 -0.150861415947226"
        rpy="0 0 0" />
      <mass
        value="1.06633596148158" />
      <inertia
        ixx="0.00308887307089837"
        ixy="2.15389313208844E-06"
        ixz="-3.35568750684746E-08"
        iyy="0.00346888032291956"
        iyz="-0.00010095424139247"
        izz="0.000946343678350946" />
    </inertial>
    <visual>
      <origin
        xyz="0 0 0"
        rpy="0 0 0" />
      <geometry>
        <mesh
          filename="package://TSD2/meshes/RL_thigh.STL" />
      </geometry>
      <material
        name="">
        <color
          rgba="1 0.549019607843137 0 1" />
      </material>
    </visual>
    <collision>
      <origin
        xyz="0 0 0"
        rpy="0 0 0" />
      <geometry>
        <mesh
          filename="package://TSD2/meshes/RL_thigh.STL" />
      </geometry>
    </collision>
  </link>
  <joint
    name="RL_thigh_joint"
    type="revolute">
    <origin
      xyz="-0.024 0.1595 0"
      rpy="0 0 0" />
    <parent
      link="RL_hip" />
    <child
      link="RL_thigh" />
    <axis
      xyz="0 -1 0" />
    <limit
      lower="-2.4435"
      upper="2.4435"
      effort="170"
      velocity="18.8495559215388" />
  </joint>
  <link
    name="RL_calf">
    <inertial>
      <origin
        xyz="0.000129129815982121 0.0292018672993822 -0.162928540960217"
        rpy="0 0 0" />
      <mass
        value="1.09119252958064" />
      <inertia
        ixx="0.00471928904764673"
        ixy="5.12461716084034E-06"
        ixz="4.47843223797767E-07"
        iyy="0.00505716636142475"
        iyz="0.00023441371193664"
        izz="0.000982245502514578" />
    </inertial>
    <visual>
      <origin
        xyz="0 0 0"
        rpy="0 0 0" />
      <geometry>
        <mesh
          filename="package://TSD2/meshes/RL_calf.STL" />
      </geometry>
      <material
        name="">
        <color
          rgba="0.0392156862745098 0.490196078431373 0.709803921568627 1" />
      </material>
    </visual>
    <collision>
      <origin
        xyz="0 0 0"
        rpy="0 0 0" />
      <geometry>
        <mesh
          filename="package://TSD2/meshes/RL_calf.STL" />
      </geometry>
    </collision>
  </link>
  <joint
    name="RL_calf_joint"
    type="revolute">
    <origin
      xyz="0 -0.0714 -0.225"
      rpy="0 0 0" />
    <parent
      link="RL_thigh" />
    <child
      link="RL_calf" />
    <axis
      xyz="0 1 0" />
    <limit
      lower="-2.7576"
      upper="2.5831"
      effort="170"
      velocity="18.85" />
  </joint>
  <link
    name="RL_wheel">
    <inertial>
      <origin
        xyz="2.85004469394723E-05 -0.00191982582822386 4.93665264895693E-05"
        rpy="0 0 0" />
      <mass
        value="0.809759882175001" />
      <inertia
        ixx="0.00248836886460222"
        ixy="-2.34386082360881E-07"
        ixz="1.21855271308757E-06"
        iyy="0.00461927313692848"
        iyz="-4.05972264683012E-07"
        izz="0.00248977603008749" />
    </inertial>
    <visual>
      <origin
        xyz="0 0 0"
        rpy="0 0 0" />
      <geometry>
        <mesh
          filename="package://TSD2/meshes/RL_wheel.STL" />
      </geometry>
      <material
        name="">
        <color
          rgba="0.341176470588235 0.83921568627451 0.411764705882353 1" />
      </material>
    </visual>
    <collision>
      <origin
        xyz="0 0 0"
        rpy="0 0 0" />
      <geometry>
        <mesh
          filename="package://TSD2/meshes/RL_wheel.STL" />
      </geometry>
    </collision>
  </link>
  <joint
    name="RL_wheel_joint"
    type="revolute">
    <origin
      xyz="0 0.0954 -0.272"
      rpy="0 0 0" />
    <parent
      link="RL_calf" />
    <child
      link="RL_wheel" />
    <axis
      xyz="0 1 0" />
    <limit
      effort="38"
      velocity="61.785" />
  </joint>
</robot>